Workbook

Sheet All Life Carriers Profile
A1: Service-Carrier ID | B1: Paycode | C1: Full Name | D1: Active? | E1: Service Main | F1: Level | G1: Rating | H1: Broker | I1: Short Carrier Name | J1: Carrier Initial | K1: Logo | L1: Main Address | M1: City | N1: State | O1: Zip | P1: Main Phone | Q1: Agent Support Phone | R1: Public URL | S1: Agent URL | T1: Email Commission | U1: Email New Business | V1: Admin Cutoff | W1: Admin Release Date | X1: Admin Min CK | Y1: Admin Min EFT | Z1: Admin Commission Policy | AA1: Admin Chargeback Schedule | AB1: Admin Advance Cap | AC1: Admin Comm Contact | AD1: Admin Other Notes
A2: L-AAI-EZT | B2: Diamond, 95, 90, 85, 80, 75, 70, 65, 60, 55, 50, 45, 40 | C2: American Income Life EZ Term | D2: Yes | E2: Life Insurance | F2: Hide | G2: 0 | H2: Brokers Alliance | I2: Am Income - EZ Term | J2: AAI-EZT | L2: 1201 Wooded Acres Drive | M2: Wasco | N2: TX | O2: 76710 | P2: 800-433-3405 | R2: https://www.ailife.com/ | S2: https://impactaws.ailife.com/main | V2: Daily | W2: Daily | X2: 50 | Y2: 10 | Z2: N/A | AA2: Unearned;Death Claim 1-24 mos 100% | AB2: 2,000.00 max per case | AC2: 800-736-7311
A3: L-AAI-EZUL | B3: Diamond, 95, 90, 85, 80, 75, 70, 65, 60, 55, 50, 45 | C3: American Income Life EZ UL | D3: Yes | E3: Life Insurance | F3: Hide | G3: 0 | H3: Brokers Alliance | I3: Am Income - EZ UL | J3: AAI-EZUL | L3: 1201 Wooded Acres Drive | M3: Wasco | N3: TX | O3: 76710 | P3: 800-433-3405 | R3: https://www.ailife.com/ | S3: https://impactaws.ailife.com/main | V3: Daily | W3: Daily | X3: 50 | Y3: 10 | Z3: N/A | AA3: Unearned;Death Claim 1-24 mos 100% | AB3: 2,000.00 max per case | AC3: 800-736-7311
A4: L-AAI-FE | B4: Diamond, 115, 110, 105, 100, 95, 90, 85, 80, 75, 70, 65, 60, 55, 50, 45 | C4: American Income Life Final Expense | D4: Yes | E4: Life Insurance | F4: Hide | G4: 0 | H4: Brokers Alliance | I4: Am Income - FE | J4: AAI-FE | L4: 1200 Wooded Acres Drive | M4: Wasco | N4: TX | O4: 76710 | P4: 800-433-3405 | R4: https://www.ailife.com/ | S4: https://impactaws.ailife.com/main | V4: Daily | W4: Daily | X4: 50 | Y4: 10 | Z4: N/A | AA4: Unearned;Death Claim 1-24 mos 100% | AB4: 2,000.00 max per case | AC4: 800-736-7311
A5: L-AAI-HP | B5: Diamond, 110, 105, 100, 95, 90, 85, 80, 75, 70, 69, 65, 60, 55, 50, 45, 40, 0 | C5: American Income Life Home Protector | D5: Yes | E5: Life Insurance | F5: Hide | G5: 0 | H5: Brokers Alliance | I5: Am Income - Home Protector | J5: AAI-HP | L5: 1201 Wooded Acres Drive | M5: Wasco | N5: TX | O5: 76710 | P5: 800-433-3405 | R5: https://www.ailife.com/ | S5: https://impactaws.ailife.com/main | V5: Daily | W5: Daily | X5: 50 | Y5: 10 | Z5: N/A | AA5: Unearned;Death Claim 1-24 mos 100% | AB5: 2,000.00 max per case | AC5: 800-736-7311
A6: L-AAI-SP | B6: Diamond, 125, 120, 115, 110, 105, 100, 95, 90, 85, 80, 75, 70, 65, 60, 55 | C6: American Income Life Survivor Protector | D6: Yes | E6: Life Insurance | F6: Hide | G6: 0 | H6: Brokers Alliance | I6: Am Income - Survivor Protector | J6: AAI-SP | L6: 1201 Wooded Acres Drive | M6: Wasco | N6: TX | O6: 76710 | P6: 800-433-3405 | R6: https://www.ailife.com/ | S6: https://impactaws.ailife.com/main | V6: Daily | W6: Daily | X6: 50 | Y6: 10 | Z6: N/A | AA6: Unearned;Death Claim 1-24 mos 100% | AB6: 2,000.00 max per case | AC6: 800-736-7311
A7: L-ALLZ | B7: Diamond, 80, 75, 70, 65, 60, 55, 50, 45, 40, 35, 30, 25, 20, 15, 10, 5 | C7: Allianz Life Insurance Company of North America | D7: Yes | E7: Life Insurance | F7: Top | G7: 0 | H7: Brokers Alliance | I7: Allianz | J7: ALLZ | L7: PO BOX 59060 | M7: Minneapolis | N7: MN | O7: 55459 | P7: 800-950-5872 | R7: https://www.allianzlife.com/ | S7: https://www.allianzlife.com/for-financial-professionals | V7: Daily | W7: Paper ck mailed out the 15th & 30th and EFT release daily (48-72hrs) | X7: 50 | Y7: No min | Z7: No | AA7: Surrendered 1-6 mos: 100%, 7-12 mos: 50% includes death of the owner | AB7: $12,000 per policy rolling $50,000 per agent | AC7: 800-950-7372 | AD7: Only Allianz Life Pro+ (old products included for reference the past)
A8: L-ANICO | C8: American National | D8: No | E8: Life Insurance | F8: Hide | G8: 0 | H8: Brokers Alliance | I8: American National | J8: ANICO | L8: PO Box 3297 | M8: Springfield | N8: MO | O8: 65808 | P8: 888-501-4043 | Q8: 800-615-7372 | R8: https://www.americannational.com/wps/portal/ | S8: https://img.anicoweb.com/wps/portal/ | V8: Friday | W8: Checks mailed Tuesday or Weds/EFT in acct Wed | X8: 100 | Y8: No min | Z8: Non Commissionable Term: ~$62.50 | AA8: 1-6 mos 100%; 7 > varies | AB8: Depends on the agent. Not on BA. $2,500 per cycle | AC8: 888-801-8845 | AD8: **As of 12/1/2022, American National will no longer accept applications for Signature Term Life Insurance.
A9: L-ANINY | C9: American National - NY | D9: Yes | E9: Life Insurance | F9: Hide | G9: 0 | H9: Brokers Alliance | I9: American National-NY | J9: ANINY | L9: PO Box 4408 | M9: Springfield | N9: MO | O9: 65808 | P9: 866-490-3163 | Q9: 800-615-7372 | R9: https://www.americannational.com/wps/portal/ | S9: https://img.anicoweb.com/wps/portal/ | V9: Friday | W9: Checks mailed Tuesday or Weds/EFT in acct Wed | X9: 100 | Y9: No min | Z9: Non Commissionable Term: ~$62.50 | AA9: 1-6 mos 100%; 7 > varies | AB9: Depends on the agent. Not on BA. $2,500 per cycle | AC9: 888-801-8845
A10: L-ASSUR | B10: Diamond, Level 18, Level 19, Level 20, Level 22, Level 24, Level 26, Level 28, Level 30, Level 32, Level 34, Level 36, Level 38, Level 50 | C10: Assurity Life Insurance Company | D10: Yes | E10: Life Insurance | F10: Top | G10: 0 | H10: Brokers Alliance | I10: Assurity | J10: ASSUR | L10: 2000 Q Street | M10: Lincoln | N10: NE | O10: 68503 | P10: 402-476-6500 | Q10: 800-869-0355 x 4279 | R10: https://www.assurity.com/ | S10: https://www.assurity.com/agent-center | V10: Friday; Bi-Monthly | W10: Manday | X10: 250 | Y10: No min | Z10: Term/CI Non Commissionable $70 | AA10: <9--3mos CB | AB10: $1,500 per policy; max per agent $25k | AC10: 800-869-0390
A11: L-AXA | B11: Diamond, Sch 90, Sch 85, Sch 80, Sch 75, Sch 70, Sch 65, Sch 60, Sch 55, Sch 50, 50, 45, 40 | C11: AXA | D11: Yes | F11: Hide
A12: L-AMERI | C12: Ameritas | D12: No | E12: Life Insurance | F12: Hide | G12: 0 | H12: Brokers Alliance | I12: Ameritas | J12: AMERI | L12: 5900 O Street, P.O. Box 81889 | M12: Lincoln | N12: NE | O12: 68501 | P12: 800-745-1112 | R12: https://www.ameritas.com/sign-in/#tab|2 | S12: https://service.ameritas.com/service/login.asp | V12: Thursday | W12: Friday | X12: N/A | Y12: No min | Z12: Varies--Commissionable | AA12: Unearned | AB12: $5,000 per policy
A13: L-BALT-FE | B13: Diamond, 115, 110, 105, 100, 95, 90, 85, 80, 75, 70, 65, 60, 55, 50, 40 | C13: Baltimore Life - Final Expense | D13: Yes
A14: L-BALT-WL | B14: Diamond, SPWL14, SPWL13.5, SPWL13, SPWL12.5, SPWL12, SPWL11.5, SPWL11, SPWL10.5, SPWL10, SPWL9.5, SPWL9, SPWL8.5, SPWL8, SPWL7.5, SPWL7, SPWL6.5, SPWL6 | C14: Baltimore Life - SPWL | D14: Yes
A15: L-BALT-T | B15: Diamond, 60, 55, 50, 45, 40 | C15: Baltimore Life - Term | D15: Yes
A16: L-BANNR | B16: Diamond, BEGA-1, AB90, AB85, AB80, AB75, AB70, AB65, AB60, BMGA85, BMGA80, BMGA75, BMGA70, BMGA65, BMGA60, BMGA90, BEGA90, BEGA85, BEGA80, BEGA75, BEGA70, BDGA90, BDGA85, BDGA80, BDGA75, BDGA70, BDGA65, BDGA60 | C16: Banner Life Insurance Company | D16: Yes | E16: Life Insurance | F16: Mid | G16: 0 | H16: Brokers Alliance | I16: Banner (Legal Life Ins Comp.) | J16: BANNR | L16: 3275 Bennett Creek Avenue | M16: Frederick | N16: MD | O16: 21704 | P16: 301-810-4440 | Q16: 301-279-4800 | R16: https://www.lgamerica.com | S16: https://www.lgamerica.com/advisor | V16: D/W/M | W16: Checks mailed 1st, 11th and 21st/ ETfs Daily | X16: 50 | Y16: 50 | Z16: The policy fee for OPTerm 10, 15, 20, 25, and 30 is non-commissionable. | AA16: Unearned | AB16: $2,500 per policy | AC16: 800-638-8428
A17: L-BRIGT | B17: Diamond, Max Base | C17: Brighthouse Financial | D17: Yes | E17: Life Insurance | F17: Hide | G17: 0 | H17: Brokers Alliance | I17: Brighthouse (FIRNA) | J17: BRIGT | L17: 11225 N Community House Road | M17: Charlotte | N17: NY | O17: 28277 | P17: 800-882-1292 | Q17: 855-861-5300 | R17: https://www.brighthousefinancial.com/products/life-insurance/ | S17: https://www.brighthousefinancialpro.com/ | V17: Friday | W17: Wednesday | X17: N/A | Y17: No min | Z17: N/A | AA17: Unearned | AB17: No Advancement | AC17: 877-638-0411
A18: L-CORE-AGLA | B18: Diamond, 11, 10, 9, 8, 7, 6, 5, 4, 3, 2, 1 | C18: Corebridge (AGLA) | D18: Yes | E18: Life Insurance | F18: Mid | G18: 0 | H18: Brokers Alliance | I18: AGLA | J18: AGLA | L18: P.O. Box 25967 | M18: Shawnee Mission | N18: KS | O18: 66225 | P18: 800-225-5244 | R18: https://www.americangeneraltermlife.com/ | S18: https://www-1.aig.com/gpplogin | V18: Friday | W18: Tuesday | X18: 50 | Y18: 50 | Z18: Over $250K varies - $65 | AA18: 100% Month 1-6 50% Month 7-12 CB to Agent BA 40% bonus will be CB to us | AB18: $5,000 per policy | AC18: 800-255-2702
A19: L-CORE | B19: Diamond, A, B, C, D, E, F, G, H, I, J, M, N | C19: Corebridge (American General) | D19: Yes | E19: Life Insurance | F19: Top | G19: 0 | H19: Brokers Alliance | I19: Corebridge | J19: CORE | L19: P.O. Box 25967 | M19: Shawnee Mission | N19: KS | O19: 66225 | P19: 800-225-5244 | R19: https://www.americangeneraltermlife.com/ | S19: https://www-1.aig.com/gpplogin | V19: Saturday | W19: EFT deposited EVERY Tuesday/ Checks mailed every other Wed. | X19: 50 | Y19: 50 | Z19: $50.00 / Not commissionable | AA19: 1-6 Months 100% 7-12 months 50% | AB19: $5,000 per policy | AC19: 800-247-8837
A20: L-CORENY | B20: Diamond, Producer | C20: Corebridge NY | D20: Yes | E20: Life Insurance | F20: Hide | G20: 0 | H20: Brokers Alliance | I20: Corebridge-NY | J20: CORENY | L20: P.O. Box 25967 | M20: Shawnee Mission | N20: KS | O20: 66225 | P20: 800-225-5244 | R20: https://www.corebridgefinancial.com/what-we-offer/life-insurance | S20: https://live.cloud.api.aig.com | V20: Saturday | W20: EFT deposited EVERY Tuesday/ Checks mailed every other Wed. | X20: 50 | Y20: 50 | Z20: $50.00 / Not commissionable | AA20: Death Claim 1-12 mos prorated; Surrender 100% | AB20: $5,000 per policy | AC20: 800-247-8837
A21: L-CORERN | B21: Diamond, E, F, G | C21: Corebridge Renewals (American General) | D21: Yes | E21: Life Insurance | F21: TBD | G21: 0 | H21: Brokers Alliance | I21: Corebridge Renewals | J21: CORERE | L21: P.O. Box 25967 | M21: Shawnee Mission | N21: KS | O21: 66225 | P21: 800-225-5244 | R21: https://www.corebridgefinancial.com/what-we-offer/life-insurance | S21: https://live.cloud.api.aig.com | V21: Friday | W21: EFT deposited EVERY Tuesday/ Checks mailed every other Wed. | X21: 50 | Y21: 50 | Z21: $50.00 / Not commissionable | AA21: 1-6 Months 100% 7-12 months 50% | AB21: $5,000 per policy | AC21: 800-247-8838
A22: L-CORESIM | B22: Diamond, J, K, L, M, N, P, Q, T, U, R, S, Y, V, W, Z, A, B, C, D | C22: Corebridge SimpliNow | D22: Yes | F22: Hide
A23: L-COREWL | B23: Diamond, J, K, L, M, N, P, Q, T | C23: Corebridge Speciality (GIWL) | D23: Yes | E23: Life Insurance | F23: TBD | G23: 0 | H23: Brokers Alliance | I23: Corebridge-Special | J23: COREWL | L23: P.O. Box 25967 | M23: Shawnee Mission | N23: KS | O23: 66225 | P23: 800-225-5244 | R23: https://www.americangeneraltermlife.com/ | S23: https://www-1.aig.com/gpplogin/login/gp/html/en/jsp/login. | V23: Friday | W23: EFT deposited EVERY Tuesday/ Checks mailed every other Wed. | X23: 50 | Y23: 50 | Z23: $50.00 / Not commissionable | AA23: 1-6 Months 100% 7-12 months 50% | AB23: $5,000 per policy | AC23: 800-247-8837
A24: L-EQTL | B24: Diamond, 90, 85, 80, 75, 70, 65, 60, 55, 50 | C24: Equitable Life Insurance | D24: Yes | E24: Life Insurance | F24: TBD | G24: 0 | H24: Brokers Alliance | I24: Equitable Life | J24: EQTL | L24: 1290 Avenue of the Americas | M24: New York | N24: NY | O24: 10104 | P24: 800-342-4368 | Q24: 800-924-6669 | R24: https://equitable.com/customer-service/life-insurance#menu | S24: https://equitable.com/financial-professionals | V24: Daily; except renewals are 2 days before end of each month | W24: Checks mailed/EFTs sent 5-7 business days after policy is received | X24: No min | Y24: No min | Z24: $45 commissionable Level / $45 NOT commissionable on Graded | AA24: First year Graded: 100% Rescinded/Returned/Unearned: 100% | AB24: 2000 | AC24: 800-352-5122
A25: L-ETHOS | B25: Diamond, 100, 95, 90, 85, 80, 75, 70, 65, 60 | C25: Ethos Life Insurance | D25: Yes | E25: Life Insurance | F25: Top | G25: 0 | H25: Brokers Alliance | I25: Ethos (Banner) | J25: ETHOS | L25: 1606 Headway Circle 9013 | M25: Austin | N25: TX | O25: 78754 | P25: 415-915-0665 | Q25: 415-639-3968 | R25: https://www.ethoslife.com/life/ethos-term-life-insurance/ | S25: https://www.ethoslife.com/self-serve-organic/ | W25: 1st week of the month following activation | X25: undefined | Y25: undefined | AB25: No advance
A26: L-FAM | B26: Diamond, 90, 85, 80, 75, 70, 65, 50, 35 | C26: Family Life | D26: Yes | E26: Life Insurance | F26: Hide
A27: L-F&GL | B27: Diamond, LB, L2 (C), L3 (C), L4, L5, LE, L6, L7, L8, LL, LM, LN, LP, BA, L0, BB, BC, LZ | C27: Fidelity & Guaranty | D27: Yes | E27: Life Insurance | F27: Top | G27: 0 | H27: Brokers Alliance | I27: Fidelity & Guaranty | J27: F&GL | L27: 801 Grand Ave Suite 2600 | M27: Des Moines | N27: IA | O27: 50309 | P27: 888-513-8797 | R27: https://www.fglife.com/life-insurance | S27: https://saleslink.fglife.com/ | V27: Wednesday | W27: Checks mailed Monday/ EFTs released Friday | X27: 50 | Y27: 10 | Z27: $60.00 / not commissionable | AA27: 100% on 1st policy year, 50% 2nd, Over $25K 100% 0-24 mos | AB27: $3,500 per policy | AC27: 800-445-6758 | AD27: C-Carrier
A28: L-FIDEL | C28: Fidelity Life Insurance | D28: No | E28: Life Insurance | F28: TBD | G28: 0 | H28: Brokers Alliance | I28: Fidelity | J28: FIDEL | L28: 1350 E. Touhy Ave. Suite 205W | M28: Des PLaines | N28: IL | O28: 60018 | P28: 800-482-6616 | Q28: 866-853-3013 | R28: https://fidelitylife.com/ | S28: https://fidelitylife.com/login/ | V28: Thursday | W28: Tuesday | X28: 50 | Y28: 50 | Z28: N/A | AA28: Different for different agents | AB28: undefined | AC28: 800-369-3990 | AD28: Other product grids available by request
A29: L-FIDEL-ADB | B29: Diamond, A085, A080, A075, A070, A065, A060, A055, A050, A045, A040, A035, A030, A025, A020, A015, A010, A005 | C29: Fidelity ADB | D29: Yes
A30: L-FIDEL-FEGI | B30: Diamond, FG22, FG20, FG17, FG15, FG12, FG10, FG07, FG05, FG02, FG01, FG97, FG95, FG92, FG90 | C30: Fidelity FE & GI | D30: Yes
A31: L-FIDELHY | B31: Diamond, H115, H110, H105, H100, H095, H090, H085, H080, H075, H070, H065, H060, H055, H050, H045, H040, H035, H030, H025, H020, H015, H010, H005 | C31: Fidelity Hybrid | D31: Yes | F31: Hide
A32: L-FIDEL-RDSL | B32: Diamond, S085, S080, S075, S070, S065, S060, S055, S050, S045, S040, S035, S030, S025, S020, S015, S010, S005 | C32: Fidelity RDSL | D32: Yes
A33: L-FORESTL | C33: Foresters Financial | D33: No | E33: Life Insurance | F33: TBD | G33: 0 | H33: Brokers Alliance | I33: Foresters Old | J33: FORESLIFE | L33: 2221 Kenmore Ave Suite 108 | M33: Buffalo | N33: NY | O33: 14207 | P33: 800-828-1540 | R33: https://www.foresters.com/en/contact-us | S33: https://myezbiz.foresters.com/my.policy | V33: Wednesday | W33: Friday | X33: N/A | Y33: 50 | Z33: Varies | AA33: Unearned | AB33: Varies | AC33: 866-466-7166
A34: L-FORESPL | B34: Diamond, PLR MGA1, PLR GA02, PLR GA01, PLR AGT12, PLR AGT11, PLR AGT10, PLR AGT09, PLR AGT08, PLR AGT07, PLR AGT06, PLR AGT05, PLR AGT04, PLR AGT03, PLR AGT02, PLR AGT01 | C34: Foresters Planright | D34: Yes | E34: Life Insurance | F34: TBD | G34: 0 | H34: Brokers Alliance | I34: Foresters Traditional- Planright | J34: FORESPL | L34: 2221 Kenmore Ave Suite 108 | M34: Buffalo | N34: NY | O34: 14207 | P34: 800-828-1540 | R34: https://www.foresters.com/en/contact-us | S34: https://myezbiz.foresters.com/my.policy | V34: Wednesday | W34: Friday | X34: N/A | Y34: 50 | Z34: Varies | AA34: Unearned | AB34: Varies | AC34: 866-466-7166
A35: L-FORESTR | B35: Diamond, MGA 4, MGA 3, MGA 2, MGA 1, GA 3, GA 2, GA 1, Agent 11, Agent 10, Agent 9, Agent 8, Agent 7, Agent 6, Agent 5, Agent 4, Agent 3, Agent 2, Agent 1A | C35: Foresters Traditional | D35: Yes | F35: Top | I35: Foresters Traditional | J35: FORESTL
A36: L-FORESNY | B36: Diamond, GA 3, GA 2, GA 1, Agent 11, Agent 10, Agent 9, Agent 8, Agent 7, Agent 6, Agent 5, Agent 4, Agent 3, Agent 2, Agent 1A | C36: Foresters Traditional - NY | D36: Yes | E36: Life Insurance | F36: TBD | G36: 0 | H36: Brokers Alliance | I36: Foresters Traditional - NY | J36: FORESNY | L36: 2222 Kenmore Ave Suite 108 | M36: Buffalo | N36: NY | O36: 14207 | P36: 800-828-1541 | R36: https://www.foresters.com/en/contact-us | S36: https://myezbiz.foresters.com/my.policy | V36: Wednesday | W36: Friday | X36: N/A | Y36: 50 | Z36: Varies | AA36: Unearned | AB36: Medical-Non Commissionable | AC36: 866-466-7166 | AD36: *Commission Capped - Maximum commission age is 65 for Advantage Plus
A37: L-GERB | B37: Diamond, Level 3, Level 2, Level 1 | C37: Gerber Life Insurance | D37: Yes | E37: Life Insurance | F37: Hide | G37: 0 | H37: Brokers Alliance | I37: Gerber Life | J37: GERB | L37: 445 State Street | M37: Fremont | N37: MI | O37: 49412 | P37: 800-704-2180 | Q37: 800-428-4947 | R37: https://www.gerberlife.com/customer-service/contact-gerber-life | S37: https://www.gerberlife.com/gl/ap/view/agency/login.jsp | V37: Thursday | W37: Wednesday | X37: 25 | Y37: 25 | Z37: N/A | AA37: Death Claim within 1st year 100% 2nd yr 50% | AB37: As earned and only pay thru 1st year | AC37: 800-428-4947 | AD37: Face Amount split for state of Florida is ≤ $99,999, ≥ $100,000
A38: L-GLOAT | B38: Diamond, IND90, IND85, IND80, IND75, IND70, IND65, IND60, IND55, IND50, IND45, IND40 | C38: Global Atlantic Financial Group | D38: Yes | E38: Life Insurance | F38: TBD | G38: 0 | H38: Brokers Alliance | I38: Global Atlantic | J38: GLOAT | L38: 30 Hudson Yards 500 WEst 33rd St | M38: New York | N38: NY | O38: 10001 | P38: 866-645-2449 | Q38: 833-275-4248 | R38: https://www.globalatlantic.com/ | S38: https://auth.login.globalatlantic.com/user/login/public | V38: EFT: Friday; Check: Last business day | W38: EFT: Tuesday/Wednesday; Checks: Monthly first day following month | X38: 50 | Y38: 50 | Z38: N/A | AA38: 1-6 mos 100%; 7-12 mos 50% | AB38: Must be approved | AC38: 855-887-4487 | AD38: ECV Rider increases the target premium on the policy.
A39: L-GWEST | B39: Diamond, 110, 105, 100, 95, 90, 85, 80, 75, 70, 65, 60, 55, 50 | C39: Great Western | D39: Yes
A40: L-GCU | B40: Diamond, 115, 110, 105, 100, 90, 80, 70, 60 | C40: Greek Catholic Union Life Insurance | D40: Yes | E40: Life Insurance | F40: TBD | G40: 0 | H40: Brokers Alliance | I40: Greek Catholic Union | J40: GCU | L40: 5400 Tuscaraws Road | M40: Beaver | N40: PA | O40: 15009 | P40: 855-306-0607 | Q40: 800-722-4428 | R40: https://gcuusa.com/ | S40: https://portal.gcuusaonline.com/wps/portal | W40: Thursday | X40: No min | Y40: No min | AA40: Chargeback is prorated based on premiums paid during the first year that the certificate is in | AB40: 3000 | AC40: 800-722-4428
...

Sheet L-AAI-EZT
A1: Row | B1: Service-Carrier ID | C1: Product Tier | D1: Types | E1: State Available | F1: Old Product name | G1: Sub-Name | H1: Sub-type | I1: Length | J1: Product Name Full | K1: Product Real | L1: All Vendor paycodes | M1: Product | N1: Criteria | O1: Notes | P1: Diamond | Q1: 95 | R1: 90 | S1: 85 | T1: 80 | U1: 75 | V1: 70 | W1: 65 | X1: 60 | Y1: 55 | Z1: 50 | AA1: 45 | AB1: 40
A2: 1 | B2: L-AAI-EZT | D2: Term | E2: All Avail. | F2: EZ Term 10 | H2: Term | I2: 10 | J2: EZ Term 10 Year | K2: Yes | L2: Diamond, 95, 90, 85, 80, 75, 70, 65, 60, 55, 50, 45, 40 | M2: EZ Term 10 | N2: Sub type: 10 Year Term | State: Alabama, Alaska, Arizona, Arkansas, California, Colorado, Connecticut, Delaware, Florida, Georgia, Hawaii, Idaho, Illinois, Indiana, Iowa, Kansas, Kentucky, Louisiana, Maine, Maryland, Massachusetts, Michigan, Minnesota, Mississippi, Missouri, Montana, Nebraska, Nevada, New Hampshire, New Jersey, New Mexico, North Carolina, North Dakota, Ohio, Oklahoma, Oregon, Pennsylvania, Rhode Island, South Carolina, South Dakota, Tennessee, Texas, Utah, Vermont, Virginia, Washington, West Virginia, Wisconsin, Wyoming | P2: 80 | Q2: 80 | R2: 75 | S2: 70 | T2: 65 | U2: 60 | V2: 55 | W2: 50 | X2: 45 | Y2: 40 | Z2: 35 | AA2: 30 | AB2: 25
A3: 2 | B3: L-AAI-EZT | C3: TBD | D3: Term | E3: All Avail. | F3: EZ Term 20 | H3: Term | I3: 20 | J3: EZ Term 20 Year | K3: Yes | L3: Diamond, 95, 90, 85, 80, 75, 70, 65, 60, 55, 50, 45, 40 | M3: EZ Term 20 | N3: Sub type: 20 Year Term | State: Alabama, Alaska, Arizona, Arkansas, California, Colorado, Connecticut, Delaware, Florida, Georgia, Hawaii, Idaho, Illinois, Indiana, Iowa, Kansas, Kentucky, Louisiana, Maine, Maryland, Massachusetts, Michigan, Minnesota, Mississippi, Missouri, Montana, Nebraska, Nevada, New Hampshire, New Jersey, New Mexico, North Carolina, North Dakota, Ohio, Oklahoma, Oregon, Pennsylvania, Rhode Island, South Carolina, South Dakota, Tennessee, Texas, Utah, Vermont, Virginia, Washington, West Virginia, Wisconsin, Wyoming | P3: 99 | Q3: 95 | R3: 90 | S3: 85 | T3: 80 | U3: 75 | V3: 70 | W3: 65 | X3: 60 | Y3: 55 | Z3: 50 | AA3: 45 | AB3: 40
A4: 3 | B4: L-AAI-EZT | C4: TBD | D4: Term | E4: All Avail. | F4: EZ Term 30 | H4: Term | I4: 30 | J4: EZ Term 30 Year | K4: Yes | L4: Diamond, 95, 90, 85, 80, 75, 70, 65, 60, 55, 50, 45, 40 | M4: EZ Term 30 | N4: Sub type: 30 Year Term | State: Alabama, Alaska, Arizona, Arkansas, California, Colorado, Connecticut, Delaware, Florida, Georgia, Hawaii, Idaho, Illinois, Indiana, Iowa, Kansas, Kentucky, Louisiana, Maine, Maryland, Massachusetts, Michigan, Minnesota, Mississippi, Missouri, Montana, Nebraska, Nevada, New Hampshire, New Jersey, New Mexico, North Carolina, North Dakota, Ohio, Oklahoma, Oregon, Pennsylvania, Rhode Island, South Carolina, South Dakota, Tennessee, Texas, Utah, Vermont, Virginia, Washington, West Virginia, Wisconsin, Wyoming | P4: 99 | Q4: 95 | R4: 90 | S4: 85 | T4: 80 | U4: 75 | V4: 70 | W4: 65 | X4: 60 | Y4: 55 | Z4: 50 | AA4: 45 | AB4: 40

Sheet L-AAI-EZUL
A1: Row | B1: Service-Carrier ID | C1: Tier | D1: Types | E1: State Available | F1: Old Product name | G1: Sub-Name | H1: Sub-type | I1: Length | J1: Product Name Full | K1: Product Real | L1: All Vendor paycodes | M1: Product | N1: Criteria | O1: Notes | P1: Diamond | Q1: 95 | R1: 90 | S1: 85 | T1: 80 | U1: 75 | V1: 70 | W1: 65 | X1: 60 | Y1: 55 | Z1: 50 | AA1: 45
A2: 1 | B2: L-AAI-EZUL | C2: TBD | D2: Perm | E2: All Avail. | F2: EZ UL | G2: Target | H2: Term | I2: Lifetime | J2: EZ UL (Target) | K2: Yes | L2: Diamond, 95, 90, 85, 80, 75, 70, 65, 60, 55, 50, 45 | M2: EZ UL | N2: Sub type: Target | State: All Available | Type: Perm | P2: 99 | Q2: 95 | R2: 90 | S2: 85 | T2: 80 | U2: 75 | V2: 70 | W2: 65 | X2: 60 | Y2: 55 | Z2: 50 | AA2: 45
A3: 2 | B3: L-AAI-EZUL | C3: TBD | D3: Perm | E3: All Avail. | F3: Excess of Target | H3: UL | I3: Lifetime | J3: EZ UL (Excess of Target) | K3: No | L3: Diamond, 95, 90, 85, 80, 75, 70, 65, 60, 55, 50, 45 | M3: EZ UL | N3: Sub type: Excess of Target | State: All Available | Excess year: 1+ | Type: Perm | Q3: 2.5 | R3: 2.5 | S3: 2.5 | T3: 2.5 | U3: 2 | V3: 2 | W3: 2 | X3: 2 | Y3: 2 | Z3: 2 | AA3: 2
A4: 3 | B4: L-AAI-EZUL | C4: TBD | D4: Perm | E4: All Avail. | F4: Renewal Years 2-6 | H4: UL | I4: Lifetime | J4: EZ UL (Renewal Years 2-6) | K4: No | L4: Diamond, 95, 90, 85, 80, 75, 70, 65, 60, 55, 50, 45 | M4: EZ UL | N4: Renewal year: 2 to 6 | State: All Available | Q4: 2.5 | R4: 2.5 | S4: 2.5 | T4: 2.5 | U4: 2 | V4: 2 | W4: 2 | X4: 2 | Y4: 2 | Z4: 2 | AA4: 2

Sheet L-AAI-FE
A1: Row | B1: Service-Carrier ID | C1: Product Tier | D1: Types | E1: State Available | F1: Old Product name | G1: Sub-Name | H1: Sub-type | I1: Length | J1: Product Name Full | K1: Product Real | L1: All Vendor paycodes | M1: Product | N1: Criteria | O1: Notes | P1: Diamond | Q1: 115 | R1: 110 | S1: 105 | T1: 100 | U1: 95 | V1: 90 | W1: 85 | X1: 80 | Y1: 75 | Z1: 70 | AA1: 65 | AB1: 60 | AC1: 55 | AD1: 50 | AE1: 45
A2: 1 | B2: L-AAI-FE | C2: TBD | D2: Final Expense | E2: All Avail. | G2: Ages 0-79 | H2: FE | I2: 80 | J2: Immediate Death Benefit Age 0-79 | K2: Yes | L2: Diamond, 115, 110, 105, 100, 95, 90, 85, 80, 75, 70, 65, 60, 55, 50, 45 | M2: Immediate Death Benefit | N2: Issue age: 0 to 79 | State: All Available | P2: 119 | Q2: 115 | R2: 110 | S2: 105 | T2: 100 | U2: 95 | V2: 90 | W2: 85 | X2: 80 | Y2: 75 | Z2: 70 | AA2: 65 | AB2: 60 | AC2: 55 | AD2: 50 | AE2: 45
A3: 2 | B3: L-AAI-FE | C3: TBD | D3: Final Expense | E3: All Avail. | H3: FE | I3: 80 | J3: Immediate Death Benefit Age 0-79 (Renewal Years 2-10) | K3: No | L3: Diamond, 115, 110, 105, 100, 95, 90, 85, 80, 75, 70, 65, 60, 55, 50, 45 | M3: Immediate Death Benefit | N3: Issue age: 0 to 79 | Renewal year: 2 to 10 | State: All Available | Q3: 7 | R3: 6.75 | S3: 6.5 | T3: 6 | U3: 5.5 | V3: 5 | W3: 4.5 | X3: 4 | Y3: 3.5 | Z3: 3 | AA3: 2.5 | AB3: 2 | AC3: 1.5 | AD3: 1 | AE3: 0.5
A4: 3 | B4: L-AAI-FE | C4: TBD | D4: Final Expense | E4: All Avail. | G4: Ages 80-85 | H4: FE | I4: 6 | J4: Immediate Death Benefit Age 80-85 | K4: Yes | L4: Diamond, 115, 110, 105, 100, 95, 90, 85, 80, 75, 70, 65, 60, 55, 50, 45 | M4: Immediate Death Benefit | N4: Issue age: 80 to 85 | State: All Available | P4: 84 | Q4: 80 | R4: 75 | S4: 70 | T4: 65 | U4: 60 | V4: 55 | W4: 50 | X4: 45 | Y4: 40 | Z4: 35 | AA4: 30 | AB4: 25 | AC4: 20 | AD4: 15 | AE4: 10
A5: 4 | B5: L-AAI-FE | C5: TBD | D5: Final Expense | E5: All Avail. | H5: FE | I5: 6 | J5: Immediate Death Benefit Age 80-85 (Renewal Years 2-10) | K5: No | L5: Diamond, 115, 110, 105, 100, 95, 90, 85, 80, 75, 70, 65, 60, 55, 50, 45 | M5: Immediate Death Benefit | N5: Issue age: 80 to 85 | Renewal year: 2 to 10 | State: All Available | Q5: 5 | R5: 4.5 | S5: 4 | T5: 3 | U5: 2.75 | V5: 2.5 | W5: 2.25 | X5: 2 | Y5: 1.75 | Z5: 1.5 | AA5: 1.25 | AB5: 1 | AC5: 0.75 | AD5: 0.5 | AE5: 0.25
A6: 5 | B6: L-AAI-FE | C6: TBD | D6: Final Expense | E6: All Avail. | G6: Ages 0-79 | H6: FE | I6: 80 | J6: Return Of Premium Plan Age 0-79 | K6: Yes | L6: Diamond, 115, 110, 105, 100, 95, 90, 85, 80, 75, 70, 65, 60, 55, 50, 45 | M6: Return Of Premium Plan | N6: Issue age: 0 to 79 | State: All Available | P6: 104 | Q6: 100 | R6: 95 | S6: 90 | T6: 85 | U6: 80 | V6: 75 | W6: 70 | X6: 65 | Y6: 60 | Z6: 55 | AA6: 50 | AB6: 47.5 | AC6: 45 | AD6: 42.5 | AE6: 40
A7: 6 | B7: L-AAI-FE | C7: TBD | D7: Final Expense | E7: All Avail. | H7: FE | I7: 80 | J7: Return Of Premium Plan Age 0-79 (Renewal Years 2-10) | K7: No | L7: Diamond, 115, 110, 105, 100, 95, 90, 85, 80, 75, 70, 65, 60, 55, 50, 45 | M7: Return Of Premium Plan | N7: Issue age: 0 to 79 | Renewal year: 2 to 10 | State: All Available | Q7: 5.25 | R7: 4.75 | S7: 4 | T7: 3.25 | U7: 3 | V7: 2.75 | W7: 2.5 | X7: 2.25 | Y7: 2 | Z7: 1.75 | AA7: 1.5 | AB7: 1.25 | AC7: 1 | AD7: 0.75 | AE7: 0.5
A8: 7 | B8: L-AAI-FE | C8: TBD | D8: Final Expense | E8: All Avail. | G8: Ages 80-85 | H8: FE | I8: 6 | J8: Return Of Premium Plan Age 80-85 | K8: Yes | L8: Diamond, 115, 110, 105, 100, 95, 90, 85, 80, 75, 70, 65, 60, 55, 50, 45 | M8: Return Of Premium Plan | N8: Issue age: 80 to 85 | State: All Available | P8: 84 | Q8: 80 | R8: 75 | S8: 70 | T8: 65 | U8: 60 | V8: 55 | W8: 50 | X8: 45 | Y8: 40 | Z8: 35 | AA8: 30 | AB8: 25 | AC8: 20 | AD8: 15 | AE8: 10
A9: 8 | B9: L-AAI-FE | C9: TBD | D9: Final Expense | E9: All Avail. | H9: FE | I9: 6 | J9: Return Of Premium Plan Age 80-85 (Renewal Years 2-10) | K9: No | L9: Diamond, 115, 110, 105, 100, 95, 90, 85, 80, 75, 70, 65, 60, 55, 50, 45 | M9: Return Of Premium Plan | N9: Issue age: 80 to 85 | Renewal year: 2 to 10 | State: All Available | Q9: 5 | R9: 4.5 | S9: 4 | T9: 3.25 | U9: 3 | V9: 2.75 | W9: 2.5 | X9: 2.25 | Y9: 2 | Z9: 1.75 | AA9: 1.5 | AB9: 1.25 | AC9: 1 | AD9: 0.75 | AE9: 0.25
A10: 9 | B10: L-AAI-FE | C10: TBD | D10: Final Expense | E10: All Avail. | G10: Ages 0-79 | H10: FE | I10: 80 | J10: Graded Death Benefit Age 0-79 | K10: Yes | L10: Diamond, 115, 110, 105, 100, 95, 90, 85, 80, 75, 70, 65, 60, 55, 50, 45 | M10: Graded Death Benefit | N10: Issue age: 0 to 79 | State: All Available | P10: 104 | Q10: 100 | R10: 95 | S10: 90 | T10: 85 | U10: 80 | V10: 75 | W10: 70 | X10: 65 | Y10: 60 | Z10: 55 | AA10: 50 | AB10: 47.5 | AC10: 45 | AD10: 42.5 | AE10: 40
A11: 10 | B11: L-AAI-FE | C11: TBD | D11: Final Expense | E11: All Avail. | H11: FE | I11: 80 | J11: Graded Death Benefit Age 0-79 (Renewal Years 2-10) | K11: No | L11: Diamond, 115, 110, 105, 100, 95, 90, 85, 80, 75, 70, 65, 60, 55, 50, 45 | M11: Graded Death Benefit | N11: Issue age: 0 to 79 | Renewal year: 2 to 10 | State: All Available | Q11: 5.25 | R11: 4.75 | S11: 4 | T11: 3.25 | U11: 3 | V11: 2.75 | W11: 2.5 | X11: 2.25 | Y11: 2 | Z11: 1.75 | AA11: 1.5 | AB11: 1.25 | AC11: 1 | AD11: 0.75 | AE11: 0.25
A12: 11 | B12: L-AAI-FE | C12: TBD | D12: Final Expense | E12: All Avail. | G12: Ages 80-85 | H12: FE | I12: 6 | J12: Graded Death Benefit Age 80-85 | K12: Yes | L12: Diamond, 115, 110, 105, 100, 95, 90, 85, 80, 75, 70, 65, 60, 55, 50, 45 | M12: Graded Death Benefit | N12: Issue age: 80 to 85 | State: All Available | P12: 84 | Q12: 80 | R12: 75 | S12: 70 | T12: 65 | U12: 60 | V12: 55 | W12: 50 | X12: 45 | Y12: 40 | Z12: 35 | AA12: 30 | AB12: 25 | AC12: 20 | AD12: 15 | AE12: 10
A13: 12 | B13: L-AAI-FE | C13: TBD | D13: Final Expense | E13: All Avail. | H13: FE | I13: 6 | J13: Graded Death Benefit Age 80-85 (Renewal Years 2-10) | K13: No | L13: Diamond, 115, 110, 105, 100, 95, 90, 85, 80, 75, 70, 65, 60, 55, 50, 45 | M13: Graded Death Benefit | N13: Issue age: 80 to 85 | Renewal year: 2 to 10 | State: All Available | Q13: 5 | R13: 4.5 | S13: 4 | T13: 3.25 | U13: 3 | V13: 2.75 | W13: 2.5 | X13: 2.25 | Y13: 2 | Z13: 1.75 | AA13: 1.5 | AB13: 1.25 | AC13: 1 | AD13: 0.75 | AE13: 0.25

Sheet L-AAI-HP
A1: Row | B1: Service-Carrier ID | C1: Product Tier | D1: Types | E1: State Available | F1: Old Product name | G1: Sub-Name | H1: Sub-type | I1: Length | J1: Product Name Full | K1: Product Real | L1: All Vendor paycodes | M1: Product | N1: Criteria | O1: Notes | P1: Diamond | Q1: 110 | R1: 105 | S1: 100 | T1: 95 | U1: 90 | V1: 85 | W1: 80 | X1: 75 | Y1: 70 | Z1: 69 | AA1: 65 | AB1: 60 | AC1: 55 | AD1: 50 | AE1: 45 | AF1: 40 | AG1: 0
A2: 1 | B2: L-AAI-HP | C2: TBD | D2: Unique | E2: All Avail. | H2: TBD | I2: 20 | J2: Home Protector 20 Year | K2: Yes | L2: Diamond, 110, 105, 100, 95, 90, 85, 80, 75, 70, 69, 65, 60, 55, 50, 45, 40, 0 | M2: Home Protector | N2: Sub type: 20 | State: All Available | P2: 114 | Q2: 110 | R2: 105 | S2: 100 | T2: 95 | U2: 90 | V2: 85 | W2: 80 | X2: 75 | Y2: 70 | Z2: 69 | AA2: 65 | AB2: 60 | AC2: 55 | AD2: 50 | AE2: 45 | AF2: 40 | AG2: 0
A3: 2 | B3: L-AAI-HP | C3: TBD | D3: Unique | E3: All Avail. | H3: TBD | I3: 30 | J3: Home Protector 30 Year | K3: Yes | L3: Diamond, 110, 105, 100, 95, 90, 85, 80, 75, 70, 69, 65, 60, 55, 50, 45, 40, 0 | M3: Home Protector | N3: Sub type: 30 | State: All Available | P3: 114 | Q3: 110 | R3: 105 | S3: 100 | T3: 95 | U3: 90 | V3: 85 | W3: 80 | X3: 75 | Y3: 70 | Z3: 69 | AA3: 65 | AB3: 60 | AC3: 55 | AD3: 50 | AE3: 45 | AF3: 40 | AG3: 0

Sheet L-AAI-SP
A1: Row | B1: Service-Carrier ID | C1: Product Tier | D1: Types | E1: State Available | F1: Old Product name | G1: Sub-Name | H1: Sub-type | I1: Length | J1: Product Name Full | K1: Product Real | L1: All Vendor paycodes | M1: Product | N1: Criteria | O1: Notes | P1: Diamond | Q1: 125 | R1: 120 | S1: 115 | T1: 110 | U1: 105 | V1: 100 | W1: 95 | X1: 90 | Y1: 85 | Z1: 80 | AA1: 75 | AB1: 70 | AC1: 65 | AD1: 60 | AE1: 55
A2: 1 | B2: L-AAI-SP | C2: TBD | D2: Unique | E2: All Avail. | F2: Survivor Protector | H2: TBD | I2: Lifetime | J2: Survivor Protector | K2: Yes | L2: Diamond, 125, 120, 115, 110, 105, 100, 95, 90, 85, 80, 75, 70, 65, 60, 55 | M2: Survivor Protector | N2: State: All Available | P2: 129 | Q2: 125 | R2: 120 | S2: 115 | T2: 110 | U2: 105 | V2: 100 | W2: 95 | X2: 90 | Y2: 85 | Z2: 80 | AA2: 75 | AB2: 70 | AC2: 65 | AD2: 60 | AE2: 55

Sheet L-ALLZ
A1: Row | B1: Service-Carrier ID | C1: Product Tier | D1: Types | E1: State Available | F1: Old Product name | G1: Sub-Name | H1: Sub-type | I1: Length | J1: Product Name Full | K1: Product Real | L1: All Vendor paycodes | M1: Product | N1: Criteria | O1: Notes | P1: Diamond | Q1: 80 | R1: 75 | S1: 70 | T1: 65 | U1: 60 | V1: 55 | W1: 50 | X1: 45 | Y1: 40 | Z1: 35 | AA1: 30 | AB1: 25 | AC1: 20 | AD1: 15 | AE1: 10 | AF1: 5
A2: 1 | B2: L-ALLZ | C2: TBD | D2: Perm | E2: All Avail. | F2: Allianz Life Pro+ Advantage | G2: Option A | H2: IUL | I2: Lifetime | J2: Allianz Life Pro+ Advantage (Option A) | K2: Yes | L2: Diamond, 80, 75, 70, 65, 60, 55, 50, 45, 40, 35, 30, 25, 20, 15, 10, 5 | M2: Allianz Life Pro+ Advantage | N2: Sub type: Option A | State: All Available | P2: 124 | Q2: 100 | R2: 95 | S2: 90 | T2: 85 | U2: 80 | V2: 75 | W2: 70 | X2: 65 | Y2: 60 | Z2: 55 | AA2: 50 | AB2: 45 | AC2: 40 | AD2: 35 | AE2: 30 | AF2: 25
A3: 2 | B3: L-ALLZ | C3: TBD | D3: Perm | E3: All Avail. | F3: Year 1 Excess and Years 2-10 Target and Excess | G3: Option A | H3: IUL | I3: Lifetime | J3: Allianz Life Pro+ Advantage (A: Yr 1-10 Excess) | K3: No | L3: Diamond, 80, 75, 70, 65, 60, 55, 50, 45, 40, 35, 30, 25, 20, 15, 10, 5 | M3: Allianz Life Pro+ Advantage | N3: Excess year: 1 to 10 | Q3: 2.5 | R3: 1.75 | S3: 1.75 | T3: 1.25 | U3: 0.75 | V3: 0.75 | W3: 0.75 | X3: 0.75 | Y3: 0.75 | Z3: 0.5 | AA3: 0.5 | AB3: 0.5 | AC3: 0.5 | AD3: 0.5 | AE3: 0.5 | AF3: 0.5
A4: 3 | B4: L-ALLZ | C4: TBD | D4: Perm | E4: All Avail. | F4: Allianz Life Pro+ Advantage | G4: Option B | H4: IUL | I4: Lifetime | J4: Allianz Life Pro+ Advantage (Option B) | K4: Yes | L4: Diamond, 80, 75, 70, 65, 60, 55, 50, 45, 40, 35, 30, 25, 20, 15, 10, 5 | M4: Allianz Life Pro+ Advantage | N4: Sub type: Option B | State: All Available | P4: 52 | Q4: 50 | R4: 47.5 | S4: 45 | T4: 42.5 | U4: 40 | V4: 37.5 | W4: 35 | X4: 32.5 | Y4: 30 | Z4: 27.5 | AA4: 25 | AB4: 22.5 | AC4: 20 | AD4: 17.5 | AE4: 15 | AF4: 12.5
A5: 4 | B5: L-ALLZ | C5: TBD | D5: Perm | E5: All Avail. | F5: Year 1 Target Premium Years 2-6 | G5: Option B | H5: IUL | I5: Lifetime | J5: Allianz Life Pro+ Advantage (B: Target 1-6) | K5: No | L5: Diamond, 80, 75, 70, 65, 60, 55, 50, 45, 40, 35, 30, 25, 20, 15, 10, 5 | M5: Allianz Life Pro+ Advantage | N5: Sub type: Year 1 Target Premium Years 2-6 | Policy year: 2 to 6 | Q5: 13.5 | R5: 12.8 | S5: 12.1 | T5: 11.4 | U5: 10.7 | V5: 10 | W5: 9.3 | X5: 8.6 | Y5: 7.9 | Z5: 7.2 | AA5: 6.5 | AB5: 5.8 | AC5: 5.1 | AD5: 4.4 | AE5: 3.7 | AF5: 3
A6: 5 | B6: L-ALLZ | C6: TBD | D6: Perm | E6: All Avail. | F6: Year 1 Excess and Years 2-10 Target and Excess | G6: Option B | H6: IUL | I6: Lifetime | J6: Allianz Life Pro+ Advantage (B: Excess 1-10) | K6: No | L6: Diamond, 80, 75, 70, 65, 60, 55, 50, 45, 40, 35, 30, 25, 20, 15, 10, 5 | M6: Allianz Life Pro+ Advantage | N6: Excess year: 1 to 10 | Q6: 2.5 | R6: 1.75 | S6: 1.75 | T6: 1.25 | U6: 0.75 | V6: 0.75 | W6: 0.75 | X6: 0.75 | Y6: 0.75 | Z6: 0.5 | AA6: 0.5 | AB6: 0.5 | AC6: 0.5 | AD6: 0.5 | AE6: 0.5 | AF6: 0.5

Sheet L-ASSUR
A1: Row | B1: Service-Carrier ID | C1: Product Tier | D1: Types | E1: State Available | F1: Old Product name | G1: Sub-Name | H1: Sub-type | I1: Length | J1: Product Name Full | K1: Product Real | L1: All Vendor paycodes | M1: Product | N1: Criteria | O1: Notes | P1: Diamond | Q1: Level 18 | R1: Level 19 | S1: Level 20 | T1: Level 22 | U1: Level 24 | V1: Level 26 | W1: Level 28 | X1: Level 30 | Y1: Level 32 | Z1: Level 34 | AA1: Level 36 | AB1: Level 38 | AC1: Level 50
A2: 1 | B2: L-ASSUR | C2: TBD | D2: Perm | E2: All Avail. | H2: WL | I2: Lifetime | J2: Assurity Whole Life Pay for Life | K2: Yes | L2: Diamond, Level 18, Level 19, Level 20, Level 22, Level 24, Level 26, Level 28, Level 30, Level 32, Level 34, Level 36, Level 38, Level 50 | M2: Assurity Whole Life Pay for Life | O2: Type: Perm State: All Avail. Product Name: Assurity Whole Life Pay for Life | P2: 97 | Q2: 80 | R2: 77.5 | S2: 75 | T2: 72.5 | U2: 70 | V2: 67.5 | W2: 65 | X2: 62.5 | Y2: 60 | Z2: 57.5 | AA2: 55 | AB2: 52.5 | AC2: 50
A3: 2 | B3: L-ASSUR | C3: TBD | D3: Perm | E3: All Avail. | H3: WL | I3: Lifetime | J3: Assurity Whole Life Pay for Life (Years 2-5) | K3: No | L3: Diamond, Level 18, Level 19, Level 20, Level 22, Level 24, Level 26, Level 28, Level 30, Level 32, Level 34, Level 36, Level 38, Level 50 | M3: Years 2-5 | O3: Product Name: Years 2-5 | Q3: 6.5 | R3: 6.5 | S3: 6.25 | T3: 6.25 | U3: 6 | V3: 5.75 | W3: 5.5 | X3: 5.25 | Y3: 5 | Z3: 5 | AA3: 5 | AB3: 5 | AC3: 5
A4: 3 | B4: L-ASSUR | C4: TBD | D4: Perm | E4: All Avail. | H4: WL | I4: Lifetime | J4: Assurity Whole Life Pay for Life (Years 6-10) | K4: No | L4: Diamond, Level 18, Level 19, Level 20, Level 22, Level 24, Level 26, Level 28, Level 30, Level 32, Level 34, Level 36, Level 38, Level 50 | M4: Years 6-10 | O4: Product Name: Years 6-10 | Q4: 3.5 | R4: 3.5 | S4: 3.25 | T4: 3.25 | U4: 3 | V4: 2.75 | W4: 2.5 | X4: 2.25 | Y4: 2 | Z4: 2 | AA4: 2 | AB4: 2 | AC4: 2
A5: 4 | B5: L-ASSUR | C5: TBD | D5: Perm | E5: All Avail. | H5: WL | I5: Lifetime | J5: Assurity Whole Life Pay for Life (Years 11+) | K5: No | L5: Diamond, Level 18, Level 19, Level 20, Level 22, Level 24, Level 26, Level 28, Level 30, Level 32, Level 34, Level 36, Level 38, Level 50 | M5: Years 11+ | O5: Product Name: Years 11+ | Q5: 1 | R5: 1 | S5: 1 | T5: 1 | U5: 0.75 | V5: 0.75 | W5: 0.75 | X5: 0.75 | Y5: 0.5 | Z5: 0.5 | AA5: 0.5 | AB5: 0.5 | AC5: 0.5
A6: 5 | B6: L-ASSUR | C6: TBD | D6: Perm | E6: All Avail. | G6: Ages 0-45 | H6: WL | I6: Lifetime | J6: Assurity Whole Life Pay to Age 65 | K6: Yes | L6: Diamond, Level 18, Level 19, Level 20, Level 22, Level 24, Level 26, Level 28, Level 30, Level 32, Level 34, Level 36, Level 38, Level 50 | M6: Assurity Whole Life Pay to Age 65 | O6: Type: Perm State: All Avail. Product Name: Assurity Whole Life Pay to Age 65 Sub Name: Ages 0-45 | P6: 67 | Q6: 62.5 | R6: 60 | S6: 57.5 | T6: 55 | U6: 52.5 | V6: 50 | W6: 47.5 | X6: 45 | Y6: 42.5 | Z6: 40 | AA6: 37.5 | AB6: 35 | AC6: 32.5
A7: 6 | B7: L-ASSUR | C7: TBD | D7: Perm | E7: All Avail. | H7: WL | I7: Lifetime | J7: Assurity Whole Life Pay to Age 65 (Years 2-5) | K7: No | L7: Diamond, Level 18, Level 19, Level 20, Level 22, Level 24, Level 26, Level 28, Level 30, Level 32, Level 34, Level 36, Level 38, Level 50 | M7: Years 2-5 | O7: Product Name: Years 2-5 | Q7: 3.5 | R7: 3.5 | S7: 3.25 | T7: 3.25 | U7: 3 | V7: 2.75 | W7: 2.5 | X7: 2.25 | Y7: 2 | Z7: 2 | AA7: 2 | AB7: 2 | AC7: 2
A8: 7 | B8: L-ASSUR | C8: TBD | D8: Perm | E8: All Avail. | H8: WL | I8: Lifetime | J8: Assurity Whole Life Pay to Age 65 (Years 6+) | K8: No | L8: Diamond, Level 18, Level 19, Level 20, Level 22, Level 24, Level 26, Level 28, Level 30, Level 32, Level 34, Level 36, Level 38, Level 50 | M8: Years 6+ | O8: Product Name: Years 6+ | Q8: 1 | R8: 1 | S8: 1 | T8: 1 | U8: 0.75 | V8: 0.75 | W8: 0.75 | X8: 0.75 | Y8: 0.5 | Z8: 0.5 | AA8: 0.5 | AB8: 0.5 | AC8: 0.5
A9: 8 | B9: L-ASSUR | C9: TBD | D9: Perm | E9: All Avail. | G9: Ages 46-54 | H9: WL | I9: Lifetime | J9: Assurity Whole Life Pay to Age 65 | K9: Yes | L9: Diamond, Level 18, Level 19, Level 20, Level 22, Level 24, Level 26, Level 28, Level 30, Level 32, Level 34, Level 36, Level 38, Level 50 | M9: Assurity Whole Life Pay to Age 65 | O9: Type: Perm State: All Avail. Product Name: Assurity Whole Life Pay to Age 65 Sub Name: Ages 46-54 | P9: 37.5 | Q9: 37.5 | R9: 36 | S9: 34 | T9: 32 | U9: 30 | V9: 28 | W9: 26 | X9: 24 | Y9: 22 | Z9: 20 | AA9: 18 | AB9: 18 | AC9: 16
A10: 9 | B10: L-ASSUR | C10: TBD | D10: Perm | E10: All Avail. | H10: WL | I10: Lifetime | J10: Assurity Whole Life Pay to Age 65 (Renewals) | K10: No | L10: Diamond, Level 18, Level 19, Level 20, Level 22, Level 24, Level 26, Level 28, Level 30, Level 32, Level 34, Level 36, Level 38, Level 50 | M10: Renewals | O10: Product Name: Renewals | Q10: 1 | R10: 1 | S10: 1 | T10: 1 | U10: 0.75 | V10: 0.75 | W10: 0.75 | X10: 0.75 | Y10: 0.5 | Z10: 0.5 | AA10: 0.5 | AB10: 0.5 | AC10: 0.5
A11: 10 | B11: L-ASSUR | C11: TBD | D11: Perm | E11: All Avail. | H11: WL | I11: Lifetime | J11: Assurity Whole Life 20 Pay | K11: Yes | L11: Diamond, Level 18, Level 19, Level 20, Level 22, Level 24, Level 26, Level 28, Level 30, Level 32, Level 34, Level 36, Level 38, Level 50 | M11: Assurity Whole Life 20 Pay | O11: Type: Perm State: All Avail. Product Name: Assurity Whole Life 20 Pay | P11: 67 | Q11: 62.5 | R11: 60 | S11: 57.5 | T11: 55 | U11: 52.5 | V11: 50 | W11: 47.5 | X11: 45 | Y11: 42.5 | Z11: 40 | AA11: 37.5 | AB11: 35 | AC11: 32.5
A12: 11 | B12: L-ASSUR | C12: TBD | D12: Perm | E12: All Avail. | H12: WL | I12: Lifetime | J12: Assurity Whole Life 20 Pay (Years 2-5) | K12: No | L12: Diamond, Level 18, Level 19, Level 20, Level 22, Level 24, Level 26, Level 28, Level 30, Level 32, Level 34, Level 36, Level 38, Level 50 | M12: Years 2-5 | O12: Product Name: Years 2-5 | Q12: 3.5 | R12: 3.5 | S12: 3.25 | T12: 3.25 | U12: 3 | V12: 2.75 | W12: 2.5 | X12: 2.25 | Y12: 2 | Z12: 2 | AA12: 2 | AB12: 2 | AC12: 2
A13: 12 | B13: L-ASSUR | C13: TBD | D13: Perm | E13: All Avail. | H13: WL | I13: Lifetime | J13: Assurity Whole Life 20 Pay (Years 6+) | K13: No | L13: Diamond, Level 18, Level 19, Level 20, Level 22, Level 24, Level 26, Level 28, Level 30, Level 32, Level 34, Level 36, Level 38, Level 50 | M13: Years 6+ | O13: Product Name: Years 6+ | Q13: 1 | R13: 1 | S13: 1 | T13: 1 | U13: 0.75 | V13: 0.75 | W13: 0.75 | X13: 0.75 | Y13: 0.5 | Z13: 0.5 | AA13: 0.5 | AB13: 0.5 | AC13: 0.5
A14: 13 | B14: L-ASSUR | C14: TBD | D14: Perm | E14: All Avail. | H14: WL | I14: Lifetime | J14: Assurity Whole Life 10 Pay | K14: Yes | L14: Diamond, Level 18, Level 19, Level 20, Level 22, Level 24, Level 26, Level 28, Level 30, Level 32, Level 34, Level 36, Level 38, Level 50 | M14: Assurity Whole Life 10 Pay | O14: Type: Perm State: All Avail. Product Name: Assurity Whole Life 10 Pay | P14: 37.5 | Q14: 37.5 | R14: 36 | S14: 34 | T14: 32 | U14: 30 | V14: 28 | W14: 26 | X14: 24 | Y14: 22 | Z14: 20 | AA14: 18 | AB14: 18 | AC14: 16
A15: 14 | B15: L-ASSUR | C15: TBD | D15: Perm | E15: All Avail. | H15: WL | I15: Lifetime | J15: Assurity Whole Life 10 Pay (Renewals) | K15: No | L15: Diamond, Level 18, Level 19, Level 20, Level 22, Level 24, Level 26, Level 28, Level 30, Level 32, Level 34, Level 36, Level 38, Level 50 | M15: Renewals | O15: Product Name: Renewals | Q15: 1 | R15: 1 | S15: 1 | T15: 1 | U15: 0.75 | V15: 0.75 | W15: 0.75 | X15: 0.75 | Y15: 0.5 | Z15: 0.5 | AA15: 0.5 | AB15: 0.5 | AC15: 0.5
A16: 15 | B16: L-ASSUR | C16: TBD | D16: Perm | E16: All Avail. | H16: WL | I16: Lifetime | J16: Assurity Whole Life Paid Up Additions Rider | K16: No | L16: Diamond, Level 18, Level 19, Level 20, Level 22, Level 24, Level 26, Level 28, Level 30, Level 32, Level 34, Level 36, Level 38, Level 50 | M16: Assurity Whole Life Paid Up Additions Rider | O16: Type: Perm State: All Avail. Product Name: Assurity Whole Life Paid Up Additions Rider | P16: 2.5 | Q16: 2.5 | R16: 2.4 | S16: 2.4 | T16: 2.3 | U16: 2.2 | V16: 2.1 | W16: 2 | X16: 2 | Y16: 2 | Z16: 1.75 | AA16: 1.75 | AB16: 1.75 | AC16: 1.75
A17: 16 | B17: L-ASSUR | C17: TBD | D17: Perm | E17: All Avail. | H17: WL | I17: Lifetime | J17: Assurity Whole Life Paid Up Additions Rider (Renewals) | K17: No | L17: Diamond, Level 18, Level 19, Level 20, Level 22, Level 24, Level 26, Level 28, Level 30, Level 32, Level 34, Level 36, Level 38, Level 50 | M17: Renewals | O17: Product Name: Renewals | Q17: 2.5 | R17: 2.4 | S17: 2.4 | T17: 2.3 | U17: 2.2 | V17: 2.1 | W17: 2 | X17: 2 | Y17: 2 | Z17: 1.75 | AA17: 1.75 | AB17: 1.75 | AC17: 1.75
A18: 17 | B18: L-ASSUR | C18: TBD | D18: Term | E18: All Avail. | H18: Term | I18: 10 | J18: 10 Year Term | K18: Yes | L18: Diamond, Level 18, Level 19, Level 20, Level 22, Level 24, Level 26, Level 28, Level 30, Level 32, Level 34, Level 36, Level 38, Level 50 | M18: 10 Year Term | O18: Type: Term State: All Avail. Product Name: 10 Year Term | P18: 87 | Q18: 80 | R18: 75 | S18: 70 | T18: 65 | U18: 60 | V18: 55 | W18: 50 | X18: 45 | Y18: 40 | Z18: 35 | AA18: 30 | AB18: 25 | AC18: 20
A19: 18 | B19: L-ASSUR | C19: TBD | D19: Term | E19: All Avail. | H19: Term | I19: 10 | J19: 10 Year Term (Years 2-10) | K19: No | L19: Diamond, Level 18, Level 19, Level 20, Level 22, Level 24, Level 26, Level 28, Level 30, Level 32, Level 34, Level 36, Level 38, Level 50 | M19: Years 2-10 | O19: Product Name: Years 2-10 | Q19: 1 | R19: 1 | S19: 1 | T19: 1 | U19: 0.75 | V19: 0.75 | W19: 0.75 | X19: 0.5 | Y19: 0.5 | Z19: 0.5 | AA19: 0.25 | AB19: 0.25 | AC19: 0.25
A20: 19 | B20: L-ASSUR | C20: TBD | D20: Term | E20: All Avail. | H20: Term | I20: 15 | J20: 15 Year Term | K20: Yes | L20: Diamond, Level 18, Level 19, Level 20, Level 22, Level 24, Level 26, Level 28, Level 30, Level 32, Level 34, Level 36, Level 38, Level 50 | M20: 15 Year Term | O20: Type: Term State: All Avail. Product Name: 15 Year Term | P20: 92 | Q20: 85 | R20: 80 | S20: 75 | T20: 70 | U20: 65 | V20: 60 | W20: 55 | X20: 50 | Y20: 45 | Z20: 40 | AA20: 35 | AB20: 30 | AC20: 25
A21: 20 | B21: L-ASSUR | C21: TBD | D21: Term | E21: All Avail. | H21: Term | I21: 15 | J21: 15 Year Term (Years 2-10) | K21: No | L21: Diamond, Level 18, Level 19, Level 20, Level 22, Level 24, Level 26, Level 28, Level 30, Level 32, Level 34, Level 36, Level 38, Level 50 | M21: Years 2-10 | O21: Product Name: Years 2-10 | Q21: 1 | R21: 1 | S21: 1 | T21: 1 | U21: 0.75 | V21: 0.75 | W21: 0.75 | X21: 0.5 | Y21: 0.5 | Z21: 0.5 | AA21: 0.25 | AB21: 0.25 | AC21: 0.25
A22: 21 | B22: L-ASSUR | C22: TBD | D22: Term | E22: All Avail. | H22: Term | I22: 20 | J22: 20 Year Term | K22: Yes | L22: Diamond, Level 18, Level 19, Level 20, Level 22, Level 24, Level 26, Level 28, Level 30, Level 32, Level 34, Level 36, Level 38, Level 50 | M22: 20 Year Term | O22: Type: Term State: All Avail. Product Name: 20 and 30 Year Term | P22: 107 | Q22: 95 | R22: 90 | S22: 85 | T22: 80 | U22: 75 | V22: 70 | W22: 65 | X22: 60 | Y22: 55 | Z22: 50 | AA22: 45 | AB22: 40 | AC22: 35
A23: 22 | B23: L-ASSUR | C23: TBD | D23: Term | E23: All Avail. | H23: Term | I23: 20 | J23: 20 Year Term (Years 2-10) | K23: No | L23: Diamond, Level 18, Level 19, Level 20, Level 22, Level 24, Level 26, Level 28, Level 30, Level 32, Level 34, Level 36, Level 38, Level 50 | M23: Years 2-10 | O23: Product Name: Years 2-10 | Q23: 1 | R23: 1 | S23: 1 | T23: 1 | U23: 0.75 | V23: 0.75 | W23: 0.75 | X23: 0.5 | Y23: 0.5 | Z23: 0.5 | AA23: 0.25 | AB23: 0.25 | AC23: 0.25
A24: 23 | B24: L-ASSUR | C24: TBD | D24: Perm | E24: All Avail. | H24: SPWL | I24: Lifetime | J24: Assurity Single Premium Whole Life | K24: Yes | L24: Diamond, Level 18, Level 19, Level 20, Level 22, Level 24, Level 26, Level 28, Level 30, Level 32, Level 34, Level 36, Level 38, Level 50 | M24: Assurity Single Premium Whole Life | O24: Type: Perm State: All Avail. Product Name: Assurity Single Premium Whole Life | P24: 10 | Q24: 10 | R24: 10 | S24: 9.75 | T24: 9.5 | U24: 9.25 | V24: 9 | W24: 8.75 | X24: 8.5 | Y24: 8.5 | Z24: 8.5 | AA24: 8.5 | AB24: 8.5 | AC24: 8.5
A25: 24 | B25: L-ASSUR | C25: TBD | D25: Sing Prem | E25: All Avail. | H25: SPWL | I25: Lifetime | J25: Assurity Single Premium Whole Life (Single Premium Insurance Rider) | K25: No | L25: Diamond, Level 18, Level 19, Level 20, Level 22, Level 24, Level 26, Level 28, Level 30, Level 32, Level 34, Level 36, Level 38, Level 50 | M25: Single Premium Insurance Rider | O25: Type: Sing Prem State: All Avail. Product Name: Single Premium Insurance Rider | P25: 3.5 | Q25: 3.5 | R25: 3.5 | S25: 3 | T25: 3 | U25: 3 | V25: 3 | W25: 3 | X25: 3 | Y25: 3 | Z25: 3 | AA25: 3 | AB25: 3 | AC25: 3
A26: 25 | B26: L-ASSUR | C26: TBD | D26: Perm | E26: All Avail. | G26: Ages 0-75 | H26: UL | I26: Lifetime | J26: Assurity Universal Life | K26: Yes | L26: Diamond, Level 18, Level 19, Level 20, Level 22, Level 24, Level 26, Level 28, Level 30, Level 32, Level 34, Level 36, Level 38, Level 50 | M26: Assurity Universal Life | O26: Type: Perm State: All Avail. Product Name: Assurity Universal Life Sub Name: Ages 0-75 | P26: 97 | Q26: 85 | R26: 82.5 | S26: 80 | T26: 77.5 | U26: 75 | V26: 72.5 | W26: 70 | X26: 67.5 | Y26: 65 | Z26: 62.5 | AA26: 60 | AB26: 57.5 | AC26: 55
A27: 26 | B27: L-ASSUR | C27: TBD | D27: Perm | E27: All Avail. | H27: UL | I27: Lifetime | J27: Assurity Universal Life (Years 2-10) | K27: No | L27: Diamond, Level 18, Level 19, Level 20, Level 22, Level 24, Level 26, Level 28, Level 30, Level 32, Level 34, Level 36, Level 38, Level 50 | M27: Years 2-10 | O27: Product Name: Years 2-10 | Q27: 3 | R27: 3 | S27: 2.75 | T27: 2.75 | U27: 2.5 | V27: 2.25 | W27: 2 | X27: 1.75 | Y27: 1.5 | Z27: 1.5 | AA27: 1.5 | AB27: 1.5 | AC27: 1.5
A28: 27 | B28: L-ASSUR | C28: TBD | D28: Perm | E28: All Avail. | H28: UL | I28: Lifetime | J28: Assurity Universal Life (Years 11+) | K28: No | L28: Diamond, Level 18, Level 19, Level 20, Level 22, Level 24, Level 26, Level 28, Level 30, Level 32, Level 34, Level 36, Level 38, Level 50 | M28: Years 11+ | O28: Product Name: Years 11+ | Q28: 1 | R28: 1 | S28: 1 | T28: 1 | U28: 0.75 | V28: 0.75 | W28: 0.75 | X28: 0.75 | Y28: 0.5 | Z28: 0.5 | AA28: 0.5 | AB28: 0.5 | AC28: 0.5
A29: 28 | B29: L-ASSUR | C29: TBD | D29: Perm | E29: All Avail. | G29: Ages 76-80 | H29: UL | I29: Lifetime | J29: Assurity Universal Life | K29: Yes | L29: Diamond, Level 18, Level 19, Level 20, Level 22, Level 24, Level 26, Level 28, Level 30, Level 32, Level 34, Level 36, Level 38, Level 50 | M29: Assurity Universal Life | O29: Type: Perm State: All Avail. Product Name: Assurity Universal Life Sub Name: Ages 76-80 | P29: 57 | Q29: 55 | R29: 52.5 | S29: 50 | T29: 47.5 | U29: 45 | V29: 42.5 | W29: 40 | X29: 37.5 | Y29: 35 | Z29: 32.5 | AA29: 30 | AB29: 27.5 | AC29: 25
A30: 29 | B30: L-ASSUR | C30: TBD | D30: Perm | E30: All Avail. | H30: UL | I30: Lifetime | J30: Assurity Universal Life (Years 2-10) | K30: No | L30: Diamond, Level 18, Level 19, Level 20, Level 22, Level 24, Level 26, Level 28, Level 30, Level 32, Level 34, Level 36, Level 38, Level 50 | M30: Years 2-10 | O30: Product Name: Years 2-10 | Q30: 3 | R30: 3 | S30: 2.75 | T30: 2.75 | U30: 2.5 | V30: 2.25 | W30: 2 | X30: 1.75 | Y30: 1.5 | Z30: 1.5 | AA30: 1.5 | AB30: 1.5 | AC30: 1.5
A31: 30 | B31: L-ASSUR | C31: TBD | D31: Perm | E31: All Avail. | H31: UL | I31: Lifetime | J31: Assurity Universal Life (Years 11+) | K31: No | L31: Diamond, Level 18, Level 19, Level 20, Level 22, Level 24, Level 26, Level 28, Level 30, Level 32, Level 34, Level 36, Level 38, Level 50 | M31: Years 11+ | O31: Product Name: Years 11+ | Q31: 1 | R31: 1 | S31: 1 | T31: 1 | U31: 0.75 | V31: 0.75 | W31: 0.75 | X31: 0.75 | Y31: 0.5 | Z31: 0.5 | AA31: 0.5 | AB31: 0.5 | AC31: 0.5
A32: 31 | B32: L-ASSUR | C32: TBD | D32: Perm | E32: All Avail. | G32: Ages 81-85 | H32: UL | I32: Lifetime | J32: Assurity Universal Life | K32: Yes | L32: Diamond, Level 18, Level 19, Level 20, Level 22, Level 24, Level 26, Level 28, Level 30, Level 32, Level 34, Level 36, Level 38, Level 50 | M32: Assurity Universal Life | O32: Type: Perm State: All Avail. Product Name: Assurity Universal Life Sub Name: Ages 81-85 | P32: 37.5 | Q32: 37.5 | R32: 36 | S32: 34 | T32: 32 | U32: 30 | V32: 28 | W32: 26 | X32: 24 | Y32: 22 | Z32: 20 | AA32: 18 | AB32: 18 | AC32: 16
A33: 32 | B33: L-ASSUR | C33: TBD | D33: Perm | E33: All Avail. | H33: UL | I33: Lifetime | J33: Assurity Universal Life (Years 2-10) | K33: No | L33: Diamond, Level 18, Level 19, Level 20, Level 22, Level 24, Level 26, Level 28, Level 30, Level 32, Level 34, Level 36, Level 38, Level 50 | M33: Years 2-10 | O33: Product Name: Years 2-10 | Q33: 3 | R33: 3 | S33: 2.75 | T33: 2.75 | U33: 2.5 | V33: 2.25 | W33: 2 | X33: 1.75 | Y33: 1.5 | Z33: 1.5 | AA33: 1.5 | AB33: 1.5 | AC33: 1.5
A34: 33 | B34: L-ASSUR | C34: TBD | D34: Perm | E34: All Avail. | H34: UL | I34: Lifetime | J34: Assurity Universal Life (Years 11+) | K34: No | L34: Diamond, Level 18, Level 19, Level 20, Level 22, Level 24, Level 26, Level 28, Level 30, Level 32, Level 34, Level 36, Level 38, Level 50 | M34: Years 11+ | O34: Product Name: Years 11+ | Q34: 1 | R34: 1 | S34: 1 | T34: 1 | U34: 0.75 | V34: 0.75 | W34: 0.75 | X34: 0.75 | Y34: 0.5 | Z34: 0.5 | AA34: 0.5 | AB34: 0.5 | AC34: 0.5
A35: 34 | B35: L-ASSUR | C35: TBD | D35: Term | E35: All Avail. | H35: Term | I35: 30 | J35: 30 year Term | K35: Yes | L35: Diamond, Level 18, Level 19, Level 20, Level 22, Level 24, Level 26, Level 28, Level 30, Level 32, Level 34, Level 36, Level 38, Level 50 | M35: 30 Year Term | P35: 107 | Q35: 95 | R35: 90 | S35: 85 | T35: 80 | U35: 75 | V35: 70 | W35: 65 | X35: 60 | Y35: 55 | Z35: 50 | AA35: 45 | AB35: 40 | AC35: 35
A36: 35 | B36: L-ASSUR | C36: TBD | D36: Term | E36: All Avail. | H36: Term | I36: 30 | J36: 30 year Term (Years 2-10) | K36: No | L36: Diamond, Level 18, Level 19, Level 20, Level 22, Level 24, Level 26, Level 28, Level 30, Level 32, Level 34, Level 36, Level 38, Level 50 | M36: Years 2-10 | Q36: 1 | R36: 1 | S36: 1 | T36: 1 | U36: 0.75 | V36: 0.75 | W36: 0.75 | X36: 0.5 | Y36: 0.5 | Z36: 0.5 | AA36: 0.25 | AB36: 0.25 | AC36: 0.25

Sheet L-AXA
A1: Row | B1: Service-Carrier ID | C1: Product Tier | D1: Types | E1: State Available | F1: Old Product name | G1: Sub-Name | H1: Sub-type | I1: Length | J1: Product Name Full | K1: Product Real | L1: All Vendor paycodes | M1: Product | N1: Criteria | O1: Notes | P1: Diamond | Q1: Sch 90 | R1: Sch 85 | S1: Sch 80 | T1: Sch 75 | U1: Sch 70 | V1: Sch 65 | W1: Sch 60 | X1: Sch 55 | Y1: Sch 50 | Z1: 50 | AA1: 45 | AB1: 40
A2: 1 | B2: L-AXA | C2: TBD | I2: Lifetime | J2: IUL Protect | K2: Yes | L2: Diamond, Sch 90, Sch 85, Sch 80, Sch 75, Sch 70, Sch 65, Sch 60, Sch 55, Sch 50, 50, 45, 40 | M2: IUL Protect | O2: Type: Perm State: All Avail. Product Name: IUL Protect Sub Name: Series 160 | P2: 96 | Q2: 90 | R2: 85 | S2: 80 | T2: 75 | U2: 70 | V2: 65 | W2: 60 | X2: 55 | Y2: 50
A3: 2 | B3: L-AXA | C3: TBD | I3: Lifetime | J3: IUL Protect (Excess Year 1) | K3: No | L3: Diamond, Sch 90, Sch 85, Sch 80, Sch 75, Sch 70, Sch 65, Sch 60, Sch 55, Sch 50, 50, 45, 40 | M3: Excess Year 1 | O3: Product Name: Excess Year 1 | Q3: 2 | R3: 2 | S3: 2 | T3: 1.5 | U3: 1.5 | V3: 1.5 | W3: 1 | X3: 1 | Y3: 1
A4: 3 | B4: L-AXA | C4: TBD | I4: Lifetime | J4: IUL Protect (Years 2-10) | K4: No | L4: Diamond, Sch 90, Sch 85, Sch 80, Sch 75, Sch 70, Sch 65, Sch 60, Sch 55, Sch 50, 50, 45, 40 | M4: Years 2-10 | O4: Product Name: Years 2-10 | Q4: 1.5 | R4: 1.5 | S4: 1.5 | T4: 1.5 | U4: 1.5 | V4: 1.5 | W4: 1.5 | X4: 1.5 | Y4: 1.5
A5: 4 | B5: L-AXA | C5: TBD | I5: Lifetime | J5: IUL Protect w/ CVPlus | K5: Yes | L5: Diamond, Sch 90, Sch 85, Sch 80, Sch 75, Sch 70, Sch 65, Sch 60, Sch 55, Sch 50, 50, 45, 40 | M5: IUL Protect w/ CVPlus | O5: Type: Perm State: All Avail. Product Name: IUL Protect w/ CVPlus | P5: 24 | Q5: 24 | R5: 24 | S5: 24 | T5: 24 | U5: 24 | V5: 24 | W5: 24 | X5: 24 | Y5: 24
A6: 5 | B6: L-AXA | C6: TBD | I6: Lifetime | J6: IUL Protect w/ CVPlus (Excess Year 1) | K6: No | L6: Diamond, Sch 90, Sch 85, Sch 80, Sch 75, Sch 70, Sch 65, Sch 60, Sch 55, Sch 50, 50, 45, 40 | M6: Excess Year 1 | O6: Product Name: Excess Year 1 | Q6: 2 | R6: 1.5 | S6: 1.5 | T6: 1.5 | U6: 1.5 | V6: 1.5 | W6: 1.5 | X6: 1.5 | Y6: 1.5
A7: 6 | B7: L-AXA | C7: TBD | I7: Lifetime | J7: IUL Protect w/ CVPlus (Years 2-6*) | K7: No | L7: Diamond, Sch 90, Sch 85, Sch 80, Sch 75, Sch 70, Sch 65, Sch 60, Sch 55, Sch 50, 50, 45, 40 | M7: Years 2-6* | O7: Product Name: Years 2-6* | Q7: 4.7 | R7: 4.7 | S7: 4.7 | T7: 4.7 | U7: 4.7 | V7: 4.7 | W7: 4.7 | X7: 4.7 | Y7: 4.7
A8: 7 | B8: L-AXA | C8: TBD | I8: Lifetime | J8: IUL Protect w/ CVPlus (Years 2-10) | K8: No | L8: Diamond, Sch 90, Sch 85, Sch 80, Sch 75, Sch 70, Sch 65, Sch 60, Sch 55, Sch 50, 50, 45, 40 | M8: Years 2-10 | O8: Product Name: Years 2-10 | Q8: 1.5 | R8: 1.5 | S8: 1.5 | T8: 1.5 | U8: 1.5 | V8: 1.5 | W8: 1.5 | X8: 1.5 | Y8: 1.5
A9: 8 | B9: L-AXA | C9: TBD | I9: Lifetime | J9: BrightLife Grow | K9: Yes | L9: Diamond, Sch 90, Sch 85, Sch 80, Sch 75, Sch 70, Sch 65, Sch 60, Sch 55, Sch 50, 50, 45, 40 | M9: BrightLife Grow | O9: Type: Perm State: All Avail. Product Name: BrightLife Grow Sub Name: Series 159 | P9: 103 | Q9: 90 | R9: 85 | S9: 80 | T9: 75 | U9: 70 | V9: 65 | W9: 60 | X9: 55 | Y9: 50
A10: 9 | B10: L-AXA | C10: TBD | I10: Lifetime | J10: BrightLife Grow (Excess Year 1) | K10: No | L10: Diamond, Sch 90, Sch 85, Sch 80, Sch 75, Sch 70, Sch 65, Sch 60, Sch 55, Sch 50, 50, 45, 40 | M10: Excess Year 1 | O10: Product Name: Excess Year 1 | Q10: 2 | R10: 2 | S10: 2 | T10: 1.5 | U10: 1.5 | V10: 1.5 | W10: 1 | X10: 1 | Y10: 1
A11: 10 | B11: L-AXA | C11: TBD | I11: Lifetime | J11: BrightLife Grow (Years 2-10) | K11: No | L11: Diamond, Sch 90, Sch 85, Sch 80, Sch 75, Sch 70, Sch 65, Sch 60, Sch 55, Sch 50, 50, 45, 40 | M11: Years 2-10 | O11: Product Name: Years 2-10 | Q11: 1.5 | R11: 1.5 | S11: 1.5 | T11: 1.5 | U11: 1.5 | V11: 1.5 | W11: 1.5 | X11: 1.5 | Y11: 1.5
A12: 11 | B12: L-AXA | C12: TBD | I12: Lifetime | J12: BrightLife Grow w/CVPlus | K12: Yes | L12: Diamond, Sch 90, Sch 85, Sch 80, Sch 75, Sch 70, Sch 65, Sch 60, Sch 55, Sch 50, 50, 45, 40 | M12: BrightLife Grow w/CVPlus | O12: Type: Perm State: All Avail. Product Name: BrightLife Grow w/CVPlus | P12: 24 | Q12: 24 | R12: 24 | S12: 24 | T12: 24 | U12: 24 | V12: 24 | W12: 24 | X12: 24 | Y12: 24
A13: 12 | B13: L-AXA | C13: TBD | I13: Lifetime | J13: BrightLife Grow w/CVPlus (Excess Year 1) | K13: No | L13: Diamond, Sch 90, Sch 85, Sch 80, Sch 75, Sch 70, Sch 65, Sch 60, Sch 55, Sch 50, 50, 45, 40 | M13: Excess Year 1 | O13: Product Name: Excess Year 1 | Q13: 1.5 | R13: 1.5 | S13: 1.5 | T13: 1.5 | U13: 1.5 | V13: 1.5 | W13: 1.5 | X13: 1.5 | Y13: 1.5
A14: 13 | B14: L-AXA | C14: TBD | I14: Lifetime | J14: BrightLife Grow w/CVPlus (Years 2-6*) | K14: No | L14: Diamond, Sch 90, Sch 85, Sch 80, Sch 75, Sch 70, Sch 65, Sch 60, Sch 55, Sch 50, 50, 45, 40 | M14: Years 2-6* | O14: Product Name: Years 2-6* | Q14: 4.7 | R14: 4.7 | S14: 4.7 | T14: 4.7 | U14: 4.7 | V14: 4.7 | W14: 4.7 | X14: 4.7 | Y14: 4.7
A15: 14 | B15: L-AXA | C15: TBD | I15: Lifetime | J15: BrightLife Grow w/CVPlus (Years 2-10) | K15: No | L15: Diamond, Sch 90, Sch 85, Sch 80, Sch 75, Sch 70, Sch 65, Sch 60, Sch 55, Sch 50, 50, 45, 40 | M15: Years 2-10 | O15: Product Name: Years 2-10 | Q15: 1.5 | R15: 1.5 | S15: 1.5 | T15: 1.5 | U15: 1.5 | V15: 1.5 | W15: 1.5 | X15: 1.5 | Y15: 1.5
A16: 15 | B16: L-AXA | C16: TBD | I16: Lifetime | J16: VUL Legacy | K16: Yes | L16: Diamond, Sch 90, Sch 85, Sch 80, Sch 75, Sch 70, Sch 65, Sch 60, Sch 55, Sch 50, 50, 45, 40 | M16: VUL Legacy | O16: Type: Perm State: All Avail. Product Name: VUL Legacy Sub Name: Series 160 | P16: 93 | Q16: 90 | R16: 85 | S16: 80 | T16: 75 | U16: 70 | V16: 65 | W16: 60 | X16: 55 | Y16: 50
A17: 16 | B17: L-AXA | C17: TBD | I17: Lifetime | J17: VUL Legacy (Excess Year 1) | K17: No | L17: Diamond, Sch 90, Sch 85, Sch 80, Sch 75, Sch 70, Sch 65, Sch 60, Sch 55, Sch 50, 50, 45, 40 | M17: Excess Year 1 | O17: Product Name: Excess Year 1 | Q17: 2 | R17: 2 | S17: 2 | T17: 1.5 | U17: 1.5 | V17: 1.5 | W17: 1 | X17: 1 | Y17: 1
A18: 17 | B18: L-AXA | C18: TBD | I18: Lifetime | J18: VUL Legacy (Years 2-10) | K18: No | L18: Diamond, Sch 90, Sch 85, Sch 80, Sch 75, Sch 70, Sch 65, Sch 60, Sch 55, Sch 50, 50, 45, 40 | M18: Years 2-10 | O18: Product Name: Years 2-10 | Q18: 1.5 | R18: 1.5 | S18: 1.5 | T18: 1.5 | U18: 1.5 | V18: 1.5 | W18: 1.5 | X18: 1.5 | Y18: 1.5
A19: 18 | B19: L-AXA | C19: TBD | I19: Lifetime | J19: VUL Optimizer | K19: Yes | L19: Diamond, Sch 90, Sch 85, Sch 80, Sch 75, Sch 70, Sch 65, Sch 60, Sch 55, Sch 50, 50, 45, 40 | M19: VUL Optimizer | O19: Type: Perm State: All Avail. Product Name: VUL Optimizer Sub Name: Series 160 | P19: 99 | Q19: 90 | R19: 85 | S19: 80 | T19: 75 | U19: 70 | V19: 65 | W19: 60 | X19: 55 | Y19: 50
